Workbook
Name ScopeType: '02. State Selector'!$C$5
Name SelectedScope: '02. State Selector'!$D$4

Sheet 00. Instructions
A1: MITRA Analytics Engine v6 — How This Workbook Works
B3: ARCHITECTURE OVERVIEW
A5: 1. | B5: RAW DATA SHEETS (RAW_DISTRICT, RAW_AR_CONTENT, RAW_QUIZ) | C5: These three sheets are the ONLY place where dashboard exports get pasted. Every other sheet reads from them via live formulas. Never type analytics numbers anywhere else.
A6: 2. | B6: STATE SELECTOR (Sheet 02) | C6: Pick 'All India' or any state from the dropdown in cell D4. This single cell drives every other sheet in the workbook through the named cell 'SelectedScope'.
A7: 3. | B7: DYNAMIC DISTRICT/STATE LIST (Sheet 02, below the selector) | C7: When a state is chosen, this list shows that state's districts with live metrics. When 'All India' is chosen, it shows all 36 states instead. Header label switches automatically between STATE and DISTRICT.
A8: 4. | B8: ANALYTICS SHEETS (03-11) | C8: Every number on these sheets is a formula referencing RAW_DISTRICT / RAW_AR_CONTENT / RAW_QUIZ, filtered to the SelectedScope. Change the scope in Sheet 02 and every sheet recalculates instantly — no manual filtering.
A9: 5. | B9: CURRICULUM & QUIZ TRACKERS (Sheets 07-08) | C9: Live filterable mirrors of RAW_AR_CONTENT and RAW_QUIZ. Use the column filter buttons (Excel AutoFilter, already enabled) to drill into any field — Subject, Class, Tier, Status, Board, Language. Nothing here is typed manually.
A10: 6. | B10: GOVERNMENT KPI SUMMARY (Sheet 10) | C10: Minister-level summary that links to Sheets 03, 04, 06, 07, 08, 09. Designed to be the direct input for automated PPT generation — each row is tagged with a suggested PPT Chart Type.
B12: HOW TO REFRESH MONTHLY DATA
A14: Step 1 | B14: Export from Dashboard | C14: Dashboard → Analytics → Export → Select Month → Download district-level, AR content, and quiz CSV/Excel exports.
A15: Step 2 | B15: Paste into RAW_DISTRICT | C15: Open the RAW_DISTRICT sheet. Paste district-level figures into the matching columns (State and District columns are already pre-filled for all 36 states + all districts — just fill in the metric columns).
A16: Step 3 | B16: Paste into RAW_AR_CONTENT | C16: Open RAW_AR_CONTENT. Paste AR module performance metrics (Launches, Completion %, Pre/Post scores, etc) against the matching State + Module rows.
A17: Step 4 | B17: Paste into RAW_QUIZ | C17: Open RAW_QUIZ. Paste quiz attempt/score/completion metrics against the matching State + Quiz rows.
A18: Step 5 | B18: Pick your scope | C18: Go to Sheet 02. Choose 'All India' for the national report, or a specific state for that state's drilldown.
A19: Step 6 | B19: Review every sheet | C19: Sheets 03-11 are now populated automatically. Use Sheet 10 (Govt KPI Summary) as the master view for presentations.
A20: Step 7 | B20: Generate PPT | C20: Feed Sheet 10 to your reporting engine. Each row specifies a suggested chart type. The dynamic scope title (cell A2 on every analytics sheet) gives the correct slide subtitle automatically.
A21: Step 8 | B21: Archive | C21: Save a dated copy before refreshing next month's RAW data (e.g. MITRA_Analytics_May2026.xlsx).
B23: FORMULA COLOR CONVENTION
A25: Blue text | B25: RAW DATA — paste dashboard exports here. | C25: Found only in RAW_DISTRICT, RAW_AR_CONTENT, RAW_QUIZ.
A26: Green text | B26: LIVE FORMULA — calculated automatically. | C26: Found on every analytics sheet. Never overtype these cells.
A27: Black text | B27: Static labels and structure. | C27: Headers, section titles, fixed reference text.
B29: IMPORTANT NOTES
A31: Note | B31: All formulas use SUMPRODUCT/SUMIFS/INDEX/MATCH — compatible with Excel 2010 and newer. | C31: No FILTER(), SORT(), or UNIQUE() dynamic-array functions are used, so this file opens without repair prompts in any Excel version.
A32: Note | B32: The hidden sheet named REF contains all dropdown master lists. | C32: Do not edit, hide/unhide, or delete this sheet.
A33: Note | B33: No formula in this workbook references its own cell. | C33: Verified with automated recalculation — zero circular references, zero formula errors.

Sheet 02. State Selector
A1: STATE SELECTOR — Choose a Scope for the Entire Workbook
B3: SELECT SCOPE — choose 'All India' for national view, or a state for state + district drill-down
B4: ▶ Selected Scope: | D4: All India
B5: Scope Type: | C5: =IF($D$4="All India","NATIONAL","STATE") -> NATIONAL
B7: Below: districts of the selected state (or all states, if 'All India'). All analytics sheets (03–13) auto-recalculate for this scope — no manual filtering required. Compatible with all Excel versions (Excel 2010+) — no dynamic array functions used.
B9: =IF($D$4="All India","STATE","DISTRICT") -> STATE | C9: Live Snapshot — Active Users, Avg Quiz Score %, Module Completion %, Engagement
B10: Name | C10: Active Users | D10: Avg Quiz Score % | E10: Module Completion % | F10: Engagement Level
B11: =IFERROR(IF($D$4="All India",INDEX({"Andaman and Nicobar Islands";"Andhra Pradesh";"Arunachal Pradesh";"Assam";"Bihar";"Chandigarh";"Chhattisgarh";"Dadra and Nagar Haveli and Daman and Diu";"Delhi";"Goa";"Gujarat";"Haryana";"Himachal Pradesh";"Jammu and Kashmir";"Jharkhand";"Karnataka";"Kerala";"Ladakh";"Lakshadweep";"Madhya Pradesh";"Maharashtra";"Manipur";"Meghalaya";"Mizoram";"Nagaland";"Odisha";"Puducherry";"Punjab";"Rajasthan";"Sikkim";"Tamil Nadu";"Telangana";"Tripura";"Uttar Pradesh";"Uttarakhand";"West Bengal"},1),INDEX('RAW_DISTRICT'!$C$4:$C$745,MATCH(1,'RAW_DISTRICT'!$V$4:$V$745,0))),"") -> Andaman and Nicobar Islands | C11: =IFERROR(IF($B11="","",SUMIF(IF($D$4="All India",'RAW_DISTRICT'!$B$4:$B$745,'RAW_DISTRICT'!$C$4:$C$745),$B11,'RAW_DISTRICT'!$F$4:$F$745)),"") -> 0 | D11: =IFERROR(IF($B11="","",SUMIF(IF($D$4="All India",'RAW_DISTRICT'!$B$4:$B$745,'RAW_DISTRICT'!$C$4:$C$745),$B11,'RAW_DISTRICT'!$I$4:$I$745)/SUMIF(IF($D$4="All India",'RAW_DISTRICT'!$B$4:$B$745,'RAW_DISTRICT'!$C$4:$C$745),$B11,'RAW_DISTRICT'!$H$4:$H$745)),"") | E11: =IFERROR(IF($B11="","",SUMIF(IF($D$4="All India",'RAW_DISTRICT'!$B$4:$B$745,'RAW_DISTRICT'!$C$4:$C$745),$B11,'RAW_DISTRICT'!$K$4:$K$745)/SUMIF(IF($D$4="All India",'RAW_DISTRICT'!$B$4:$B$745,'RAW_DISTRICT'!$C$4:$C$745),$B11,'RAW_DISTRICT'!$J$4:$J$745)),"") | F11: =IFERROR(IF($C11="","",IF($C11>=AVERAGE($C$11:$C$46)*1.2,"High",IF($C11>=AVERAGE($C$11:$C$46)*0.7,"Medium","Low"))),"") -> High
B12: =IFERROR(IF($D$4="All India",INDEX({"Andaman and Nicobar Islands";"Andhra Pradesh";"Arunachal Pradesh";"Assam";"Bihar";"Chandigarh";"Chhattisgarh";"Dadra and Nagar Haveli and Daman and Diu";"Delhi";"Goa";"Gujarat";"Haryana";"Himachal Pradesh";"Jammu and Kashmir";"Jharkhand";"Karnataka";"Kerala";"Ladakh";"Lakshadweep";"Madhya Pradesh";"Maharashtra";"Manipur";"Meghalaya";"Mizoram";"Nagaland";"Odisha";"Puducherry";"Punjab";"Rajasthan";"Sikkim";"Tamil Nadu";"Telangana";"Tripura";"Uttar Pradesh";"Uttarakhand";"West Bengal"},2),INDEX('RAW_DISTRICT'!$C$4:$C$745,MATCH(2,'RAW_DISTRICT'!$V$4:$V$745,0))),"") -> Andhra Pradesh | C12: =IFERROR(IF($B12="","",SUMIF(IF($D$4="All India",'RAW_DISTRICT'!$B$4:$B$745,'RAW_DISTRICT'!$C$4:$C$745),$B12,'RAW_DISTRICT'!$F$4:$F$745)),"") -> 0 | D12: =IFERROR(IF($B12="","",SUMIF(IF($D$4="All India",'RAW_DISTRICT'!$B$4:$B$745,'RAW_DISTRICT'!$C$4:$C$745),$B12,'RAW_DISTRICT'!$I$4:$I$745)/SUMIF(IF($D$4="All India",'RAW_DISTRICT'!$B$4:$B$745,'RAW_DISTRICT'!$C$4:$C$745),$B12,'RAW_DISTRICT'!$H$4:$H$745)),"") | E12: =IFERROR(IF($B12="","",SUMIF(IF($D$4="All India",'RAW_DISTRICT'!$B$4:$B$745,'RAW_DISTRICT'!$C$4:$C$745),$B12,'RAW_DISTRICT'!$K$4:$K$745)/SUMIF(IF($D$4="All India",'RAW_DISTRICT'!$B$4:$B$745,'RAW_DISTRICT'!$C$4:$C$745),$B12,'RAW_DISTRICT'!$J$4:$J$745)),"") | F12: =IFERROR(IF($C12="","",IF($C12>=AVERAGE($C$11:$C$46)*1.2,"High",IF($C12>=AVERAGE($C$11:$C$46)*0.7,"Medium","Low"))),"") -> High
B13: =IFERROR(IF($D$4="All India",INDEX({"Andaman and Nicobar Islands";"Andhra Pradesh";"Arunachal Pradesh";"Assam";"Bihar";"Chandigarh";"Chhattisgarh";"Dadra and Nagar Haveli and Daman and Diu";"Delhi";"Goa";"Gujarat";"Haryana";"Himachal Pradesh";"Jammu and Kashmir";"Jharkhand";"Karnataka";"Kerala";"Ladakh";"Lakshadweep";"Madhya Pradesh";"Maharashtra";"Manipur";"Meghalaya";"Mizoram";"Nagaland";"Odisha";"Puducherry";"Punjab";"Rajasthan";"Sikkim";"Tamil Nadu";"Telangana";"Tripura";"Uttar Pradesh";"Uttarakhand";"West Bengal"},3),INDEX('RAW_DISTRICT'!$C$4:$C$745,MATCH(3,'RAW_DISTRICT'!$V$4:$V$745,0))),"") -> Arunachal Pradesh | C13: =IFERROR(IF($B13="","",SUMIF(IF($D$4="All India",'RAW_DISTRICT'!$B$4:$B$745,'RAW_DISTRICT'!$C$4:$C$745),$B13,'RAW_DISTRICT'!$F$4:$F$745)),"") -> 0 | D13: =IFERROR(IF($B13="","",SUMIF(IF($D$4="All India",'RAW_DISTRICT'!$B$4:$B$745,'RAW_DISTRICT'!$C$4:$C$745),$B13,'RAW_DISTRICT'!$I$4:$I$745)/SUMIF(IF($D$4="All India",'RAW_DISTRICT'!$B$4:$B$745,'RAW_DISTRICT'!$C$4:$C$745),$B13,'RAW_DISTRICT'!$H$4:$H$745)),"") | E13: =IFERROR(IF($B13="","",SUMIF(IF($D$4="All India",'RAW_DISTRICT'!$B$4:$B$745,'RAW_DISTRICT'!$C$4:$C$745),$B13,'RAW_DISTRICT'!$K$4:$K$745)/SUMIF(IF($D$4="All India",'RAW_DISTRICT'!$B$4:$B$745,'RAW_DISTRICT'!$C$4:$C$745),$B13,'RAW_DISTRICT'!$J$4:$J$745)),"") | F13: =IFERROR(IF($C13="","",IF($C13>=AVERAGE($C$11:$C$46)*1.2,"High",IF($C13>=AVERAGE($C$11:$C$46)*0.7,"Medium","Low"))),"") -> High
B14: =IFERROR(IF($D$4="All India",INDEX({"Andaman and Nicobar Islands";"Andhra Pradesh";"Arunachal Pradesh";"Assam";"Bihar";"Chandigarh";"Chhattisgarh";"Dadra and Nagar Haveli and Daman and Diu";"Delhi";"Goa";"Gujarat";"Haryana";"Himachal Pradesh";"Jammu and Kashmir";"Jharkhand";"Karnataka";"Kerala";"Ladakh";"Lakshadweep";"Madhya Pradesh";"Maharashtra";"Manipur";"Meghalaya";"Mizoram";"Nagaland";"Odisha";"Puducherry";"Punjab";"Rajasthan";"Sikkim";"Tamil Nadu";"Telangana";"Tripura";"Uttar Pradesh";"Uttarakhand";"West Bengal"},4),INDEX('RAW_DISTRICT'!$C$4:$C$745,MATCH(4,'RAW_DISTRICT'!$V$4:$V$745,0))),"") -> Assam | C14: =IFERROR(IF($B14="","",SUMIF(IF($D$4="All India",'RAW_DISTRICT'!$B$4:$B$745,'RAW_DISTRICT'!$C$4:$C$745),$B14,'RAW_DISTRICT'!$F$4:$F$745)),"") -> 0 | D14: =IFERROR(IF($B14="","",SUMIF(IF($D$4="All India",'RAW_DISTRICT'!$B$4:$B$745,'RAW_DISTRICT'!$C$4:$C$745),$B14,'RAW_DISTRICT'!$I$4:$I$745)/SUMIF(IF($D$4="All India",'RAW_DISTRICT'!$B$4:$B$745,'RAW_DISTRICT'!$C$4:$C$745),$B14,'RAW_DISTRICT'!$H$4:$H$745)),"") | E14: =IFERROR(IF($B14="","",SUMIF(IF($D$4="All India",'RAW_DISTRICT'!$B$4:$B$745,'RAW_DISTRICT'!$C$4:$C$745),$B14,'RAW_DISTRICT'!$K$4:$K$745)/SUMIF(IF($D$4="All India",'RAW_DISTRICT'!$B$4:$B$745,'RAW_DISTRICT'!$C$4:$C$745),$B14,'RAW_DISTRICT'!$J$4:$J$745)),"") | F14: =IFERROR(IF($C14="","",IF($C14>=AVERAGE($C$11:$C$46)*1.2,"High",IF($C14>=AVERAGE($C$11:$C$46)*0.7,"Medium","Low"))),"") -> High
B15: =IFERROR(IF($D$4="All India",INDEX({"Andaman and Nicobar Islands";"Andhra Pradesh";"Arunachal Pradesh";"Assam";"Bihar";"Chandigarh";"Chhattisgarh";"Dadra and Nagar Haveli and Daman and Diu";"Delhi";"Goa";"Gujarat";"Haryana";"Himachal Pradesh";"Jammu and Kashmir";"Jharkhand";"Karnataka";"Kerala";"Ladakh";"Lakshadweep";"Madhya Pradesh";"Maharashtra";"Manipur";"Meghalaya";"Mizoram";"Nagaland";"Odisha";"Puducherry";"Punjab";"Rajasthan";"Sikkim";"Tamil Nadu";"Telangana";"Tripura";"Uttar Pradesh";"Uttarakhand";"West Bengal"},5),INDEX('RAW_DISTRICT'!$C$4:$C$745,MATCH(5,'RAW_DISTRICT'!$V$4:$V$745,0))),"") -> Bihar | C15: =IFERROR(IF($B15="","",SUMIF(IF($D$4="All India",'RAW_DISTRICT'!$B$4:$B$745,'RAW_DISTRICT'!$C$4:$C$745),$B15,'RAW_DISTRICT'!$F$4:$F$745)),"") -> 0 | D15: =IFERROR(IF($B15="","",SUMIF(IF($D$4="All India",'RAW_DISTRICT'!$B$4:$B$745,'RAW_DISTRICT'!$C$4:$C$745),$B15,'RAW_DISTRICT'!$I$4:$I$745)/SUMIF(IF($D$4="All India",'RAW_DISTRICT'!$B$4:$B$745,'RAW_DISTRICT'!$C$4:$C$745),$B15,'RAW_DISTRICT'!$H$4:$H$745)),"") | E15: =IFERROR(IF($B15="","",SUMIF(IF($D$4="All India",'RAW_DISTRICT'!$B$4:$B$745,'RAW_DISTRICT'!$C$4:$C$745),$B15,'RAW_DISTRICT'!$K$4:$K$745)/SUMIF(IF($D$4="All India",'RAW_DISTRICT'!$B$4:$B$745,'RAW_DISTRICT'!$C$4:$C$745),$B15,'RAW_DISTRICT'!$J$4:$J$745)),"") | F15: =IFERROR(IF($C15="","",IF($C15>=AVERAGE($C$11:$C$46)*1.2,"High",IF($C15>=AVERAGE($C$11:$C$46)*0.7,"Medium","Low"))),"") -> High
B16: =IFERROR(IF($D$4="All India",INDEX({"Andaman and Nicobar Islands";"Andhra Pradesh";"Arunachal Pradesh";"Assam";"Bihar";"Chandigarh";"Chhattisgarh";"Dadra and Nagar Haveli and Daman and Diu";"Delhi";"Goa";"Gujarat";"Haryana";"Himachal Pradesh";"Jammu and Kashmir";"Jharkhand";"Karnataka";"Kerala";"Ladakh";"Lakshadweep";"Madhya Pradesh";"Maharashtra";"Manipur";"Meghalaya";"Mizoram";"Nagaland";"Odisha";"Puducherry";"Punjab";"Rajasthan";"Sikkim";"Tamil Nadu";"Telangana";"Tripura";"Uttar Pradesh";"Uttarakhand";"West Bengal"},6),INDEX('RAW_DISTRICT'!$C$4:$C$745,MATCH(6,'RAW_DISTRICT'!$V$4:$V$745,0))),"") -> Chandigarh | C16: =IFERROR(IF($B16="","",SUMIF(IF($D$4="All India",'RAW_DISTRICT'!$B$4:$B$745,'RAW_DISTRICT'!$C$4:$C$745),$B16,'RAW_DISTRICT'!$F$4:$F$745)),"") -> 0 | D16: =IFERROR(IF($B16="","",SUMIF(IF($D$4="All India",'RAW_DISTRICT'!$B$4:$B$745,'RAW_DISTRICT'!$C$4:$C$745),$B16,'RAW_DISTRICT'!$I$4:$I$745)/SUMIF(IF($D$4="All India",'RAW_DISTRICT'!$B$4:$B$745,'RAW_DISTRICT'!$C$4:$C$745),$B16,'RAW_DISTRICT'!$H$4:$H$745)),"") | E16: =IFERROR(IF($B16="","",SUMIF(IF($D$4="All India",'RAW_DISTRICT'!$B$4:$B$745,'RAW_DISTRICT'!$C$4:$C$745),$B16,'RAW_DISTRICT'!$K$4:$K$745)/SUMIF(IF($D$4="All India",'RAW_DISTRICT'!$B$4:$B$745,'RAW_DISTRICT'!$C$4:$C$745),$B16,'RAW_DISTRICT'!$J$4:$J$745)),"") | F16: =IFERROR(IF($C16="","",IF($C16>=AVERAGE($C$11:$C$46)*1.2,"High",IF($C16>=AVERAGE($C$11:$C$46)*0.7,"Medium","Low"))),"") -> High
B17: =IFERROR(IF($D$4="All India",INDEX({"Andaman and Nicobar Islands";"Andhra Pradesh";"Arunachal Pradesh";"Assam";"Bihar";"Chandigarh";"Chhattisgarh";"Dadra and Nagar Haveli and Daman and Diu";"Delhi";"Goa";"Gujarat";"Haryana";"Himachal Pradesh";"Jammu and Kashmir";"Jharkhand";"Karnataka";"Kerala";"Ladakh";"Lakshadweep";"Madhya Pradesh";"Maharashtra";"Manipur";"Meghalaya";"Mizoram";"Nagaland";"Odisha";"Puducherry";"Punjab";"Rajasthan";"Sikkim";"Tamil Nadu";"Telangana";"Tripura";"Uttar Pradesh";"Uttarakhand";"West Bengal"},7),INDEX('RAW_DISTRICT'!$C$4:$C$745,MATCH(7,'RAW_DISTRICT'!$V$4:$V$745,0))),"") -> Chhattisgarh | C17: =IFERROR(IF($B17="","",SUMIF(IF($D$4="All India",'RAW_DISTRICT'!$B$4:$B$745,'RAW_DISTRICT'!$C$4:$C$745),$B17,'RAW_DISTRICT'!$F$4:$F$745)),"") -> 0 | D17: =IFERROR(IF($B17="","",SUMIF(IF($D$4="All India",'RAW_DISTRICT'!$B$4:$B$745,'RAW_DISTRICT'!$C$4:$C$745),$B17,'RAW_DISTRICT'!$I$4:$I$745)/SUMIF(IF($D$4="All India",'RAW_DISTRICT'!$B$4:$B$745,'RAW_DISTRICT'!$C$4:$C$745),$B17,'RAW_DISTRICT'!$H$4:$H$745)),"") | E17: =IFERROR(IF($B17="","",SUMIF(IF($D$4="All India",'RAW_DISTRICT'!$B$4:$B$745,'RAW_DISTRICT'!$C$4:$C$745),$B17,'RAW_DISTRICT'!$K$4:$K$745)/SUMIF(IF($D$4="All India",'RAW_DISTRICT'!$B$4:$B$745,'RAW_DISTRICT'!$C$4:$C$745),$B17,'RAW_DISTRICT'!$J$4:$J$745)),"") | F17: =IFERROR(IF($C17="","",IF($C17>=AVERAGE($C$11:$C$46)*1.2,"High",IF($C17>=AVERAGE($C$11:$C$46)*0.7,"Medium","Low"))),"") -> High
B18: =IFERROR(IF($D$4="All India",INDEX({"Andaman and Nicobar Islands";"Andhra Pradesh";"Arunachal Pradesh";"Assam";"Bihar";"Chandigarh";"Chhattisgarh";"Dadra and Nagar Haveli and Daman and Diu";"Delhi";"Goa";"Gujarat";"Haryana";"Himachal Pradesh";"Jammu and Kashmir";"Jharkhand";"Karnataka";"Kerala";"Ladakh";"Lakshadweep";"Madhya Pradesh";"Maharashtra";"Manipur";"Meghalaya";"Mizoram";"Nagaland";"Odisha";"Puducherry";"Punjab";"Rajasthan";"Sikkim";"Tamil Nadu";"Telangana";"Tripura";"Uttar Pradesh";"Uttarakhand";"West Bengal"},8),INDEX('RAW_DISTRICT'!$C$4:$C$745,MATCH(8,'RAW_DISTRICT'!$V$4:$V$745,0))),"") -> Dadra and Nagar Haveli and Daman and Diu | C18: =IFERROR(IF($B18="","",SUMIF(IF($D$4="All India",'RAW_DISTRICT'!$B$4:$B$745,'RAW_DISTRICT'!$C$4:$C$745),$B18,'RAW_DISTRICT'!$F$4:$F$745)),"") -> 0 | D18: =IFERROR(IF($B18="","",SUMIF(IF($D$4="All India",'RAW_DISTRICT'!$B$4:$B$745,'RAW_DISTRICT'!$C$4:$C$745),$B18,'RAW_DISTRICT'!$I$4:$I$745)/SUMIF(IF($D$4="All India",'RAW_DISTRICT'!$B$4:$B$745,'RAW_DISTRICT'!$C$4:$C$745),$B18,'RAW_DISTRICT'!$H$4:$H$745)),"") | E18: =IFERROR(IF($B18="","",SUMIF(IF($D$4="All India",'RAW_DISTRICT'!$B$4:$B$745,'RAW_DISTRICT'!$C$4:$C$745),$B18,'RAW_DISTRICT'!$K$4:$K$745)/SUMIF(IF($D$4="All India",'RAW_DISTRICT'!$B$4:$B$745,'RAW_DISTRICT'!$C$4:$C$745),$B18,'RAW_DISTRICT'!$J$4:$J$745)),"") | F18: =IFERROR(IF($C18="","",IF($C18>=AVERAGE($C$11:$C$46)*1.2,"High",IF($C18>=AVERAGE($C$11:$C$46)*0.7,"Medium","Low"))),"") -> High
B19: =IFERROR(IF($D$4="All India",INDEX({"Andaman and Nicobar Islands";"Andhra Pradesh";"Arunachal Pradesh";"Assam";"Bihar";"Chandigarh";"Chhattisgarh";"Dadra and Nagar Haveli and Daman and Diu";"Delhi";"Goa";"Gujarat";"Haryana";"Himachal Pradesh";"Jammu and Kashmir";"Jharkhand";"Karnataka";"Kerala";"Ladakh";"Lakshadweep";"Madhya Pradesh";"Maharashtra";"Manipur";"Meghalaya";"Mizoram";"Nagaland";"Odisha";"Puducherry";"Punjab";"Rajasthan";"Sikkim";"Tamil Nadu";"Telangana";"Tripura";"Uttar Pradesh";"Uttarakhand";"West Bengal"},9),INDEX('RAW_DISTRICT'!$C$4:$C$745,MATCH(9,'RAW_DISTRICT'!$V$4:$V$745,0))),"") -> Delhi | C19: =IFERROR(IF($B19="","",SUMIF(IF($D$4="All India",'RAW_DISTRICT'!$B$4:$B$745,'RAW_DISTRICT'!$C$4:$C$745),$B19,'RAW_DISTRICT'!$F$4:$F$745)),"") -> 0 | D19: =IFERROR(IF($B19="","",SUMIF(IF($D$4="All India",'RAW_DISTRICT'!$B$4:$B$745,'RAW_DISTRICT'!$C$4:$C$745),$B19,'RAW_DISTRICT'!$I$4:$I$745)/SUMIF(IF($D$4="All India",'RAW_DISTRICT'!$B$4:$B$745,'RAW_DISTRICT'!$C$4:$C$745),$B19,'RAW_DISTRICT'!$H$4:$H$745)),"") | E19: =IFERROR(IF($B19="","",SUMIF(IF($D$4="All India",'RAW_DISTRICT'!$B$4:$B$745,'RAW_DISTRICT'!$C$4:$C$745),$B19,'RAW_DISTRICT'!$K$4:$K$745)/SUMIF(IF($D$4="All India",'RAW_DISTRICT'!$B$4:$B$745,'RAW_DISTRICT'!$C$4:$C$745),$B19,'RAW_DISTRICT'!$J$4:$J$745)),"") | F19: =IFERROR(IF($C19="","",IF($C19>=AVERAGE($C$11:$C$46)*1.2,"High",IF($C19>=AVERAGE($C$11:$C$46)*0.7,"Medium","Low"))),"") -> High
B20: =IFERROR(IF($D$4="All India",INDEX({"Andaman and Nicobar Islands";"Andhra Pradesh";"Arunachal Pradesh";"Assam";"Bihar";"Chandigarh";"Chhattisgarh";"Dadra and Nagar Haveli and Daman and Diu";"Delhi";"Goa";"Gujarat";"Haryana";"Himachal Pradesh";"Jammu and Kashmir";"Jharkhand";"Karnataka";"Kerala";"Ladakh";"Lakshadweep";"Madhya Pradesh";"Maharashtra";"Manipur";"Meghalaya";"Mizoram";"Nagaland";"Odisha";"Puducherry";"Punjab";"Rajasthan";"Sikkim";"Tamil Nadu";"Telangana";"Tripura";"Uttar Pradesh";"Uttarakhand";"West Bengal"},10),INDEX('RAW_DISTRICT'!$C$4:$C$745,MATCH(10,'RAW_DISTRICT'!$V$4:$V$745,0))),"") -> Goa | C20: =IFERROR(IF($B20="","",SUMIF(IF($D$4="All India",'RAW_DISTRICT'!$B$4:$B$745,'RAW_DISTRICT'!$C$4:$C$745),$B20,'RAW_DISTRICT'!$F$4:$F$745)),"") -> 0 | D20: =IFERROR(IF($B20="","",SUMIF(IF($D$4="All India",'RAW_DISTRICT'!$B$4:$B$745,'RAW_DISTRICT'!$C$4:$C$745),$B20,'RAW_DISTRICT'!$I$4:$I$745)/SUMIF(IF($D$4="All India",'RAW_DISTRICT'!$B$4:$B$745,'RAW_DISTRICT'!$C$4:$C$745),$B20,'RAW_DISTRICT'!$H$4:$H$745)),"") | E20: =IFERROR(IF($B20="","",SUMIF(IF($D$4="All India",'RAW_DISTRICT'!$B$4:$B$745,'RAW_DISTRICT'!$C$4:$C$745),$B20,'RAW_DISTRICT'!$K$4:$K$745)/SUMIF(IF($D$4="All India",'RAW_DISTRICT'!$B$4:$B$745,'RAW_DISTRICT'!$C$4:$C$745),$B20,'RAW_DISTRICT'!$J$4:$J$745)),"") | F20: =IFERROR(IF($C20="","",IF($C20>=AVERAGE($C$11:$C$46)*1.2,"High",IF($C20>=AVERAGE($C$11:$C$46)*0.7,"Medium","Low"))),"") -> High
B21: =IFERROR(IF($D$4="All India",INDEX({"Andaman and Nicobar Islands";"Andhra Pradesh";"Arunachal Pradesh";"Assam";"Bihar";"Chandigarh";"Chhattisgarh";"Dadra and Nagar Haveli and Daman and Diu";"Delhi";"Goa";"Gujarat";"Haryana";"Himachal Pradesh";"Jammu and Kashmir";"Jharkhand";"Karnataka";"Kerala";"Ladakh";"Lakshadweep";"Madhya Pradesh";"Maharashtra";"Manipur";"Meghalaya";"Mizoram";"Nagaland";"Odisha";"Puducherry";"Punjab";"Rajasthan";"Sikkim";"Tamil Nadu";"Telangana";"Tripura";"Uttar Pradesh";"Uttarakhand";"West Bengal"},11),INDEX('RAW_DISTRICT'!$C$4:$C$745,MATCH(11,'RAW_DISTRICT'!$V$4:$V$745,0))),"") -> Gujarat | C21: =IFERROR(IF($B21="","",SUMIF(IF($D$4="All India",'RAW_DISTRICT'!$B$4:$B$745,'RAW_DISTRICT'!$C$4:$C$745),$B21,'RAW_DISTRICT'!$F$4:$F$745)),"") -> 0 | D21: =IFERROR(IF($B21="","",SUMIF(IF($D$4="All India",'RAW_DISTRICT'!$B$4:$B$745,'RAW_DISTRICT'!$C$4:$C$745),$B21,'RAW_DISTRICT'!$I$4:$I$745)/SUMIF(IF($D$4="All India",'RAW_DISTRICT'!$B$4:$B$745,'RAW_DISTRICT'!$C$4:$C$745),$B21,'RAW_DISTRICT'!$H$4:$H$745)),"") | E21: =IFERROR(IF($B21="","",SUMIF(IF($D$4="All India",'RAW_DISTRICT'!$B$4:$B$745,'RAW_DISTRICT'!$C$4:$C$745),$B21,'RAW_DISTRICT'!$K$4:$K$745)/SUMIF(IF($D$4="All India",'RAW_DISTRICT'!$B$4:$B$745,'RAW_DISTRICT'!$C$4:$C$745),$B21,'RAW_DISTRICT'!$J$4:$J$745)),"") | F21: =IFERROR(IF($C21="","",IF($C21>=AVERAGE($C$11:$C$46)*1.2,"High",IF($C21>=AVERAGE($C$11:$C$46)*0.7,"Medium","Low"))),"") -> High
B22: =IFERROR(IF($D$4="All India",INDEX({"Andaman and Nicobar Islands";"Andhra Pradesh";"Arunachal Pradesh";"Assam";"Bihar";"Chandigarh";"Chhattisgarh";"Dadra and Nagar Haveli and Daman and Diu";"Delhi";"Goa";"Gujarat";"Haryana";"Himachal Pradesh";"Jammu and Kashmir";"Jharkhand";"Karnataka";"Kerala";"Ladakh";"Lakshadweep";"Madhya Pradesh";"Maharashtra";"Manipur";"Meghalaya";"Mizoram";"Nagaland";"Odisha";"Puducherry";"Punjab";"Rajasthan";"Sikkim";"Tamil Nadu";"Telangana";"Tripura";"Uttar Pradesh";"Uttarakhand";"West Bengal"},12),INDEX('RAW_DISTRICT'!$C$4:$C$745,MATCH(12,'RAW_DISTRICT'!$V$4:$V$745,0))),"") -> Haryana | C22: =IFERROR(IF($B22="","",SUMIF(IF($D$4="All India",'RAW_DISTRICT'!$B$4:$B$745,'RAW_DISTRICT'!$C$4:$C$745),$B22,'RAW_DISTRICT'!$F$4:$F$745)),"") -> 0 | D22: =IFERROR(IF($B22="","",SUMIF(IF($D$4="All India",'RAW_DISTRICT'!$B$4:$B$745,'RAW_DISTRICT'!$C$4:$C$745),$B22,'RAW_DISTRICT'!$I$4:$I$745)/SUMIF(IF($D$4="All India",'RAW_DISTRICT'!$B$4:$B$745,'RAW_DISTRICT'!$C$4:$C$745),$B22,'RAW_DISTRICT'!$H$4:$H$745)),"") | E22: =IFERROR(IF($B22="","",SUMIF(IF($D$4="All India",'RAW_DISTRICT'!$B$4:$B$745,'RAW_DISTRICT'!$C$4:$C$745),$B22,'RAW_DISTRICT'!$K$4:$K$745)/SUMIF(IF($D$4="All India",'RAW_DISTRICT'!$B$4:$B$745,'RAW_DISTRICT'!$C$4:$C$745),$B22,'RAW_DISTRICT'!$J$4:$J$745)),"") | F22: =IFERROR(IF($C22="","",IF($C22>=AVERAGE($C$11:$C$46)*1.2,"High",IF($C22>=AVERAGE($C$11:$C$46)*0.7,"Medium","Low"))),"") -> High
B23: =IFERROR(IF($D$4="All India",INDEX({"Andaman and Nicobar Islands";"Andhra Pradesh";"Arunachal Pradesh";"Assam";"Bihar";"Chandigarh";"Chhattisgarh";"Dadra and Nagar Haveli and Daman and Diu";"Delhi";"Goa";"Gujarat";"Haryana";"Himachal Pradesh";"Jammu and Kashmir";"Jharkhand";"Karnataka";"Kerala";"Ladakh";"Lakshadweep";"Madhya Pradesh";"Maharashtra";"Manipur";"Meghalaya";"Mizoram";"Nagaland";"Odisha";"Puducherry";"Punjab";"Rajasthan";"Sikkim";"Tamil Nadu";"Telangana";"Tripura";"Uttar Pradesh";"Uttarakhand";"West Bengal"},13),INDEX('RAW_DISTRICT'!$C$4:$C$745,MATCH(13,'RAW_DISTRICT'!$V$4:$V$745,0))),"") -> Himachal Pradesh | C23: =IFERROR(IF($B23="","",SUMIF(IF($D$4="All India",'RAW_DISTRICT'!$B$4:$B$745,'RAW_DISTRICT'!$C$4:$C$745),$B23,'RAW_DISTRICT'!$F$4:$F$745)),"") -> 0 | D23: =IFERROR(IF($B23="","",SUMIF(IF($D$4="All India",'RAW_DISTRICT'!$B$4:$B$745,'RAW_DISTRICT'!$C$4:$C$745),$B23,'RAW_DISTRICT'!$I$4:$I$745)/SUMIF(IF($D$4="All India",'RAW_DISTRICT'!$B$4:$B$745,'RAW_DISTRICT'!$C$4:$C$745),$B23,'RAW_DISTRICT'!$H$4:$H$745)),"") | E23: =IFERROR(IF($B23="","",SUMIF(IF($D$4="All India",'RAW_DISTRICT'!$B$4:$B$745,'RAW_DISTRICT'!$C$4:$C$745),$B23,'RAW_DISTRICT'!$K$4:$K$745)/SUMIF(IF($D$4="All India",'RAW_DISTRICT'!$B$4:$B$745,'RAW_DISTRICT'!$C$4:$C$745),$B23,'RAW_DISTRICT'!$J$4:$J$745)),"") | F23: =IFERROR(IF($C23="","",IF($C23>=AVERAGE($C$11:$C$46)*1.2,"High",IF($C23>=AVERAGE($C$11:$C$46)*0.7,"Medium","Low"))),"") -> High
B24: =IFERROR(IF($D$4="All India",INDEX({"Andaman and Nicobar Islands";"Andhra Pradesh";"Arunachal Pradesh";"Assam";"Bihar";"Chandigarh";"Chhattisgarh";"Dadra and Nagar Haveli and Daman and Diu";"Delhi";"Goa";"Gujarat";"Haryana";"Himachal Pradesh";"Jammu and Kashmir";"Jharkhand";"Karnataka";"Kerala";"Ladakh";"Lakshadweep";"Madhya Pradesh";"Maharashtra";"Manipur";"Meghalaya";"Mizoram";"Nagaland";"Odisha";"Puducherry";"Punjab";"Rajasthan";"Sikkim";"Tamil Nadu";"Telangana";"Tripura";"Uttar Pradesh";"Uttarakhand";"West Bengal"},14),INDEX('RAW_DISTRICT'!$C$4:$C$745,MATCH(14,'RAW_DISTRICT'!$V$4:$V$745,0))),"") -> Jammu and Kashmir | C24: =IFERROR(IF($B24="","",SUMIF(IF($D$4="All India",'RAW_DISTRICT'!$B$4:$B$745,'RAW_DISTRICT'!$C$4:$C$745),$B24,'RAW_DISTRICT'!$F$4:$F$745)),"") -> 0 | D24: =IFERROR(IF($B24="","",SUMIF(IF($D$4="All India",'RAW_DISTRICT'!$B$4:$B$745,'RAW_DISTRICT'!$C$4:$C$745),$B24,'RAW_DISTRICT'!$I$4:$I$745)/SUMIF(IF($D$4="All India",'RAW_DISTRICT'!$B$4:$B$745,'RAW_DISTRICT'!$C$4:$C$745),$B24,'RAW_DISTRICT'!$H$4:$H$745)),"") | E24: =IFERROR(IF($B24="","",SUMIF(IF($D$4="All India",'RAW_DISTRICT'!$B$4:$B$745,'RAW_DISTRICT'!$C$4:$C$745),$B24,'RAW_DISTRICT'!$K$4:$K$745)/SUMIF(IF($D$4="All India",'RAW_DISTRICT'!$B$4:$B$745,'RAW_DISTRICT'!$C$4:$C$745),$B24,'RAW_DISTRICT'!$J$4:$J$745)),"") | F24: =IFERROR(IF($C24="","",IF($C24>=AVERAGE($C$11:$C$46)*1.2,"High",IF($C24>=AVERAGE($C$11:$C$46)*0.7,"Medium","Low"))),"") -> High
B25: =IFERROR(IF($D$4="All India",INDEX({"Andaman and Nicobar Islands";"Andhra Pradesh";"Arunachal Pradesh";"Assam";"Bihar";"Chandigarh";"Chhattisgarh";"Dadra and Nagar Haveli and Daman and Diu";"Delhi";"Goa";"Gujarat";"Haryana";"Himachal Pradesh";"Jammu and Kashmir";"Jharkhand";"Karnataka";"Kerala";"Ladakh";"Lakshadweep";"Madhya Pradesh";"Maharashtra";"Manipur";"Meghalaya";"Mizoram";"Nagaland";"Odisha";"Puducherry";"Punjab";"Rajasthan";"Sikkim";"Tamil Nadu";"Telangana";"Tripura";"Uttar Pradesh";"Uttarakhand";"West Bengal"},15),INDEX('RAW_DISTRICT'!$C$4:$C$745,MATCH(15,'RAW_DISTRICT'!$V$4:$V$745,0))),"") -> Jharkhand | C25: =IFERROR(IF($B25="","",SUMIF(IF($D$4="All India",'RAW_DISTRICT'!$B$4:$B$745,'RAW_DISTRICT'!$C$4:$C$745),$B25,'RAW_DISTRICT'!$F$4:$F$745)),"") -> 0 | D25: =IFERROR(IF($B25="","",SUMIF(IF($D$4="All India",'RAW_DISTRICT'!$B$4:$B$745,'RAW_DISTRICT'!$C$4:$C$745),$B25,'RAW_DISTRICT'!$I$4:$I$745)/SUMIF(IF($D$4="All India",'RAW_DISTRICT'!$B$4:$B$745,'RAW_DISTRICT'!$C$4:$C$745),$B25,'RAW_DISTRICT'!$H$4:$H$745)),"") | E25: =IFERROR(IF($B25="","",SUMIF(IF($D$4="All India",'RAW_DISTRICT'!$B$4:$B$745,'RAW_DISTRICT'!$C$4:$C$745),$B25,'RAW_DISTRICT'!$K$4:$K$745)/SUMIF(IF($D$4="All India",'RAW_DISTRICT'!$B$4:$B$745,'RAW_DISTRICT'!$C$4:$C$745),$B25,'RAW_DISTRICT'!$J$4:$J$745)),"") | F25: =IFERROR(IF($C25="","",IF($C25>=AVERAGE($C$11:$C$46)*1.2,"High",IF($C25>=AVERAGE($C$11:$C$46)*0.7,"Medium","Low"))),"") -> High
B26: =IFERROR(IF($D$4="All India",INDEX({"Andaman and Nicobar Islands";"Andhra Pradesh";"Arunachal Pradesh";"Assam";"Bihar";"Chandigarh";"Chhattisgarh";"Dadra and Nagar Haveli and Daman and Diu";"Delhi";"Goa";"Gujarat";"Haryana";"Himachal Pradesh";"Jammu and Kashmir";"Jharkhand";"Karnataka";"Kerala";"Ladakh";"Lakshadweep";"Madhya Pradesh";"Maharashtra";"Manipur";"Meghalaya";"Mizoram";"Nagaland";"Odisha";"Puducherry";"Punjab";"Rajasthan";"Sikkim";"Tamil Nadu";"Telangana";"Tripura";"Uttar Pradesh";"Uttarakhand";"West Bengal"},16),INDEX('RAW_DISTRICT'!$C$4:$C$745,MATCH(16,'RAW_DISTRICT'!$V$4:$V$745,0))),"") -> Karnataka | C26: =IFERROR(IF($B26="","",SUMIF(IF($D$4="All India",'RAW_DISTRICT'!$B$4:$B$745,'RAW_DISTRICT'!$C$4:$C$745),$B26,'RAW_DISTRICT'!$F$4:$F$745)),"") -> 0 | D26: =IFERROR(IF($B26="","",SUMIF(IF($D$4="All India",'RAW_DISTRICT'!$B$4:$B$745,'RAW_DISTRICT'!$C$4:$C$745),$B26,'RAW_DISTRICT'!$I$4:$I$745)/SUMIF(IF($D$4="All India",'RAW_DISTRICT'!$B$4:$B$745,'RAW_DISTRICT'!$C$4:$C$745),$B26,'RAW_DISTRICT'!$H$4:$H$745)),"") | E26: =IFERROR(IF($B26="","",SUMIF(IF($D$4="All India",'RAW_DISTRICT'!$B$4:$B$745,'RAW_DISTRICT'!$C$4:$C$745),$B26,'RAW_DISTRICT'!$K$4:$K$745)/SUMIF(IF($D$4="All India",'RAW_DISTRICT'!$B$4:$B$745,'RAW_DISTRICT'!$C$4:$C$745),$B26,'RAW_DISTRICT'!$J$4:$J$745)),"") | F26: =IFERROR(IF($C26="","",IF($C26>=AVERAGE($C$11:$C$46)*1.2,"High",IF($C26>=AVERAGE($C$11:$C$46)*0.7,"Medium","Low"))),"") -> High
B27: =IFERROR(IF($D$4="All India",INDEX({"Andaman and Nicobar Islands";"Andhra Pradesh";"Arunachal Pradesh";"Assam";"Bihar";"Chandigarh";"Chhattisgarh";"Dadra and Nagar Haveli and Daman and Diu";"Delhi";"Goa";"Gujarat";"Haryana";"Himachal Pradesh";"Jammu and Kashmir";"Jharkhand";"Karnataka";"Kerala";"Ladakh";"Lakshadweep";"Madhya Pradesh";"Maharashtra";"Manipur";"Meghalaya";"Mizoram";"Nagaland";"Odisha";"Puducherry";"Punjab";"Rajasthan";"Sikkim";"Tamil Nadu";"Telangana";"Tripura";"Uttar Pradesh";"Uttarakhand";"West Bengal"},17),INDEX('RAW_DISTRICT'!$C$4:$C$745,MATCH(17,'RAW_DISTRICT'!$V$4:$V$745,0))),"") -> Kerala | C27: =IFERROR(IF($B27="","",SUMIF(IF($D$4="All India",'RAW_DISTRICT'!$B$4:$B$745,'RAW_DISTRICT'!$C$4:$C$745),$B27,'RAW_DISTRICT'!$F$4:$F$745)),"") -> 0 | D27: =IFERROR(IF($B27="","",SUMIF(IF($D$4="All India",'RAW_DISTRICT'!$B$4:$B$745,'RAW_DISTRICT'!$C$4:$C$745),$B27,'RAW_DISTRICT'!$I$4:$I$745)/SUMIF(IF($D$4="All India",'RAW_DISTRICT'!$B$4:$B$745,'RAW_DISTRICT'!$C$4:$C$745),$B27,'RAW_DISTRICT'!$H$4:$H$745)),"") | E27: =IFERROR(IF($B27="","",SUMIF(IF($D$4="All India",'RAW_DISTRICT'!$B$4:$B$745,'RAW_DISTRICT'!$C$4:$C$745),$B27,'RAW_DISTRICT'!$K$4:$K$745)/SUMIF(IF($D$4="All India",'RAW_DISTRICT'!$B$4:$B$745,'RAW_DISTRICT'!$C$4:$C$745),$B27,'RAW_DISTRICT'!$J$4:$J$745)),"") | F27: =IFERROR(IF($C27="","",IF($C27>=AVERAGE($C$11:$C$46)*1.2,"High",IF($C27>=AVERAGE($C$11:$C$46)*0.7,"Medium","Low"))),"") -> High
B28: =IFERROR(IF($D$4="All India",INDEX({"Andaman and Nicobar Islands";"Andhra Pradesh";"Arunachal Pradesh";"Assam";"Bihar";"Chandigarh";"Chhattisgarh";"Dadra and Nagar Haveli and Daman and Diu";"Delhi";"Goa";"Gujarat";"Haryana";"Himachal Pradesh";"Jammu and Kashmir";"Jharkhand";"Karnataka";"Kerala";"Ladakh";"Lakshadweep";"Madhya Pradesh";"Maharashtra";"Manipur";"Meghalaya";"Mizoram";"Nagaland";"Odisha";"Puducherry";"Punjab";"Rajasthan";"Sikkim";"Tamil Nadu";"Telangana";"Tripura";"Uttar Pradesh";"Uttarakhand";"West Bengal"},18),INDEX('RAW_DISTRICT'!$C$4:$C$745,MATCH(18,'RAW_DISTRICT'!$V$4:$V$745,0))),"") -> Ladakh | C28: =IFERROR(IF($B28="","",SUMIF(IF($D$4="All India",'RAW_DISTRICT'!$B$4:$B$745,'RAW_DISTRICT'!$C$4:$C$745),$B28,'RAW_DISTRICT'!$F$4:$F$745)),"") -> 0 | D28: =IFERROR(IF($B28="","",SUMIF(IF($D$4="All India",'RAW_DISTRICT'!$B$4:$B$745,'RAW_DISTRICT'!$C$4:$C$745),$B28,'RAW_DISTRICT'!$I$4:$I$745)/SUMIF(IF($D$4="All India",'RAW_DISTRICT'!$B$4:$B$745,'RAW_DISTRICT'!$C$4:$C$745),$B28,'RAW_DISTRICT'!$H$4:$H$745)),"") | E28: =IFERROR(IF($B28="","",SUMIF(IF($D$4="All India",'RAW_DISTRICT'!$B$4:$B$745,'RAW_DISTRICT'!$C$4:$C$745),$B28,'RAW_DISTRICT'!$K$4:$K$745)/SUMIF(IF($D$4="All India",'RAW_DISTRICT'!$B$4:$B$745,'RAW_DISTRICT'!$C$4:$C$745),$B28,'RAW_DISTRICT'!$J$4:$J$745)),"") | F28: =IFERROR(IF($C28="","",IF($C28>=AVERAGE($C$11:$C$46)*1.2,"High",IF($C28>=AVERAGE($C$11:$C$46)*0.7,"Medium","Low"))),"") -> High
B29: =IFERROR(IF($D$4="All India",INDEX({"Andaman and Nicobar Islands";"Andhra Pradesh";"Arunachal Pradesh";"Assam";"Bihar";"Chandigarh";"Chhattisgarh";"Dadra and Nagar Haveli and Daman and Diu";"Delhi";"Goa";"Gujarat";"Haryana";"Himachal Pradesh";"Jammu and Kashmir";"Jharkhand";"Karnataka";"Kerala";"Ladakh";"Lakshadweep";"Madhya Pradesh";"Maharashtra";"Manipur";"Meghalaya";"Mizoram";"Nagaland";"Odisha";"Puducherry";"Punjab";"Rajasthan";"Sikkim";"Tamil Nadu";"Telangana";"Tripura";"Uttar Pradesh";"Uttarakhand";"West Bengal"},19),INDEX('RAW_DISTRICT'!$C$4:$C$745,MATCH(19,'RAW_DISTRICT'!$V$4:$V$745,0))),"") -> Lakshadweep | C29: =IFERROR(IF($B29="","",SUMIF(IF($D$4="All India",'RAW_DISTRICT'!$B$4:$B$745,'RAW_DISTRICT'!$C$4:$C$745),$B29,'RAW_DISTRICT'!$F$4:$F$745)),"") -> 0 | D29: =IFERROR(IF($B29="","",SUMIF(IF($D$4="All India",'RAW_DISTRICT'!$B$4:$B$745,'RAW_DISTRICT'!$C$4:$C$745),$B29,'RAW_DISTRICT'!$I$4:$I$745)/SUMIF(IF($D$4="All India",'RAW_DISTRICT'!$B$4:$B$745,'RAW_DISTRICT'!$C$4:$C$745),$B29,'RAW_DISTRICT'!$H$4:$H$745)),"") | E29: =IFERROR(IF($B29="","",SUMIF(IF($D$4="All India",'RAW_DISTRICT'!$B$4:$B$745,'RAW_DISTRICT'!$C$4:$C$745),$B29,'RAW_DISTRICT'!$K$4:$K$745)/SUMIF(IF($D$4="All India",'RAW_DISTRICT'!$B$4:$B$745,'RAW_DISTRICT'!$C$4:$C$745),$B29,'RAW_DISTRICT'!$J$4:$J$745)),"") | F29: =IFERROR(IF($C29="","",IF($C29>=AVERAGE($C$11:$C$46)*1.2,"High",IF($C29>=AVERAGE($C$11:$C$46)*0.7,"Medium","Low"))),"") -> High
B30: =IFERROR(IF($D$4="All India",INDEX({"Andaman and Nicobar Islands";"Andhra Pradesh";"Arunachal Pradesh";"Assam";"Bihar";"Chandigarh";"Chhattisgarh";"Dadra and Nagar Haveli and Daman and Diu";"Delhi";"Goa";"Gujarat";"Haryana";"Himachal Pradesh";"Jammu and Kashmir";"Jharkhand";"Karnataka";"Kerala";"Ladakh";"Lakshadweep";"Madhya Pradesh";"Maharashtra";"Manipur";"Meghalaya";"Mizoram";"Nagaland";"Odisha";"Puducherry";"Punjab";"Rajasthan";"Sikkim";"Tamil Nadu";"Telangana";"Tripura";"Uttar Pradesh";"Uttarakhand";"West Bengal"},20),INDEX('RAW_DISTRICT'!$C$4:$C$745,MATCH(20,'RAW_DISTRICT'!$V$4:$V$745,0))),"") -> Madhya Pradesh | C30: =IFERROR(IF($B30="","",SUMIF(IF($D$4="All India",'RAW_DISTRICT'!$B$4:$B$745,'RAW_DISTRICT'!$C$4:$C$745),$B30,'RAW_DISTRICT'!$F$4:$F$745)),"") -> 0 | D30: =IFERROR(IF($B30="","",SUMIF(IF($D$4="All India",'RAW_DISTRICT'!$B$4:$B$745,'RAW_DISTRICT'!$C$4:$C$745),$B30,'RAW_DISTRICT'!$I$4:$I$745)/SUMIF(IF($D$4="All India",'RAW_DISTRICT'!$B$4:$B$745,'RAW_DISTRICT'!$C$4:$C$745),$B30,'RAW_DISTRICT'!$H$4:$H$745)),"") | E30: =IFERROR(IF($B30="","",SUMIF(IF($D$4="All India",'RAW_DISTRICT'!$B$4:$B$745,'RAW_DISTRICT'!$C$4:$C$745),$B30,'RAW_DISTRICT'!$K$4:$K$745)/SUMIF(IF($D$4="All India",'RAW_DISTRICT'!$B$4:$B$745,'RAW_DISTRICT'!$C$4:$C$745),$B30,'RAW_DISTRICT'!$J$4:$J$745)),"") | F30: =IFERROR(IF($C30="","",IF($C30>=AVERAGE($C$11:$C$46)*1.2,"High",IF($C30>=AVERAGE($C$11:$C$46)*0.7,"Medium","Low"))),"") -> High
B31: =IFERROR(IF($D$4="All India",INDEX({"Andaman and Nicobar Islands";"Andhra Pradesh";"Arunachal Pradesh";"Assam";"Bihar";"Chandigarh";"Chhattisgarh";"Dadra and Nagar Haveli and Daman and Diu";"Delhi";"Goa";"Gujarat";"Haryana";"Himachal Pradesh";"Jammu and Kashmir";"Jharkhand";"Karnataka";"Kerala";"Ladakh";"Lakshadweep";"Madhya Pradesh";"Maharashtra";"Manipur";"Meghalaya";"Mizoram";"Nagaland";"Odisha";"Puducherry";"Punjab";"Rajasthan";"Sikkim";"Tamil Nadu";"Telangana";"Tripura";"Uttar Pradesh";"Uttarakhand";"West Bengal"},21),INDEX('RAW_DISTRICT'!$C$4:$C$745,MATCH(21,'RAW_DISTRICT'!$V$4:$V$745,0))),"") -> Maharashtra | C31: =IFERROR(IF($B31="","",SUMIF(IF($D$4="All India",'RAW_DISTRICT'!$B$4:$B$745,'RAW_DISTRICT'!$C$4:$C$745),$B31,'RAW_DISTRICT'!$F$4:$F$745)),"") -> 0 | D31: =IFERROR(IF($B31="","",SUMIF(IF($D$4="All India",'RAW_DISTRICT'!$B$4:$B$745,'RAW_DISTRICT'!$C$4:$C$745),$B31,'RAW_DISTRICT'!$I$4:$I$745)/SUMIF(IF($D$4="All India",'RAW_DISTRICT'!$B$4:$B$745,'RAW_DISTRICT'!$C$4:$C$745),$B31,'RAW_DISTRICT'!$H$4:$H$745)),"") | E31: =IFERROR(IF($B31="","",SUMIF(IF($D$4="All India",'RAW_DISTRICT'!$B$4:$B$745,'RAW_DISTRICT'!$C$4:$C$745),$B31,'RAW_DISTRICT'!$K$4:$K$745)/SUMIF(IF($D$4="All India",'RAW_DISTRICT'!$B$4:$B$745,'RAW_DISTRICT'!$C$4:$C$745),$B31,'RAW_DISTRICT'!$J$4:$J$745)),"") | F31: =IFERROR(IF($C31="","",IF($C31>=AVERAGE($C$11:$C$46)*1.2,"High",IF($C31>=AVERAGE($C$11:$C$46)*0.7,"Medium","Low"))),"") -> High
B32: =IFERROR(IF($D$4="All India",INDEX({"Andaman and Nicobar Islands";"Andhra Pradesh";"Arunachal Pradesh";"Assam";"Bihar";"Chandigarh";"Chhattisgarh";"Dadra and Nagar Haveli and Daman and Diu";"Delhi";"Goa";"Gujarat";"Haryana";"Himachal Pradesh";"Jammu and Kashmir";"Jharkhand";"Karnataka";"Kerala";"Ladakh";"Lakshadweep";"Madhya Pradesh";"Maharashtra";"Manipur";"Meghalaya";"Mizoram";"Nagaland";"Odisha";"Puducherry";"Punjab";"Rajasthan";"Sikkim";"Tamil Nadu";"Telangana";"Tripura";"Uttar Pradesh";"Uttarakhand";"West Bengal"},22),INDEX('RAW_DISTRICT'!$C$4:$C$745,MATCH(22,'RAW_DISTRICT'!$V$4:$V$745,0))),"") -> Manipur | C32: =IFERROR(IF($B32="","",SUMIF(IF($D$4="All India",'RAW_DISTRICT'!$B$4:$B$745,'RAW_DISTRICT'!$C$4:$C$745),$B32,'RAW_DISTRICT'!$F$4:$F$745)),"") -> 0 | D32: =IFERROR(IF($B32="","",SUMIF(IF($D$4="All India",'RAW_DISTRICT'!$B$4:$B$745,'RAW_DISTRICT'!$C$4:$C$745),$B32,'RAW_DISTRICT'!$I$4:$I$745)/SUMIF(IF($D$4="All India",'RAW_DISTRICT'!$B$4:$B$745,'RAW_DISTRICT'!$C$4:$C$745),$B32,'RAW_DISTRICT'!$H$4:$H$745)),"") | E32: =IFERROR(IF($B32="","",SUMIF(IF($D$4="All India",'RAW_DISTRICT'!$B$4:$B$745,'RAW_DISTRICT'!$C$4:$C$745),$B32,'RAW_DISTRICT'!$K$4:$K$745)/SUMIF(IF($D$4="All India",'RAW_DISTRICT'!$B$4:$B$745,'RAW_DISTRICT'!$C$4:$C$745),$B32,'RAW_DISTRICT'!$J$4:$J$745)),"") | F32: =IFERROR(IF($C32="","",IF($C32>=AVERAGE($C$11:$C$46)*1.2,"High",IF($C32>=AVERAGE($C$11:$C$46)*0.7,"Medium","Low"))),"") -> High
B33: =IFERROR(IF($D$4="All India",INDEX({"Andaman and Nicobar Islands";"Andhra Pradesh";"Arunachal Pradesh";"Assam";"Bihar";"Chandigarh";"Chhattisgarh";"Dadra and Nagar Haveli and Daman and Diu";"Delhi";"Goa";"Gujarat";"Haryana";"Himachal Pradesh";"Jammu and Kashmir";"Jharkhand";"Karnataka";"Kerala";"Ladakh";"Lakshadweep";"Madhya Pradesh";"Maharashtra";"Manipur";"Meghalaya";"Mizoram";"Nagaland";"Odisha";"Puducherry";"Punjab";"Rajasthan";"Sikkim";"Tamil Nadu";"Telangana";"Tripura";"Uttar Pradesh";"Uttarakhand";"West Bengal"},23),INDEX('RAW_DISTRICT'!$C$4:$C$745,MATCH(23,'RAW_DISTRICT'!$V$4:$V$745,0))),"") -> Meghalaya | C33: =IFERROR(IF($B33="","",SUMIF(IF($D$4="All India",'RAW_DISTRICT'!$B$4:$B$745,'RAW_DISTRICT'!$C$4:$C$745),$B33,'RAW_DISTRICT'!$F$4:$F$745)),"") -> 0 | D33: =IFERROR(IF($B33="","",SUMIF(IF($D$4="All India",'RAW_DISTRICT'!$B$4:$B$745,'RAW_DISTRICT'!$C$4:$C$745),$B33,'RAW_DISTRICT'!$I$4:$I$745)/SUMIF(IF($D$4="All India",'RAW_DISTRICT'!$B$4:$B$745,'RAW_DISTRICT'!$C$4:$C$745),$B33,'RAW_DISTRICT'!$H$4:$H$745)),"") | E33: =IFERROR(IF($B33="","",SUMIF(IF($D$4="All India",'RAW_DISTRICT'!$B$4:$B$745,'RAW_DISTRICT'!$C$4:$C$745),$B33,'RAW_DISTRICT'!$K$4:$K$745)/SUMIF(IF($D$4="All India",'RAW_DISTRICT'!$B$4:$B$745,'RAW_DISTRICT'!$C$4:$C$745),$B33,'RAW_DISTRICT'!$J$4:$J$745)),"") | F33: =IFERROR(IF($C33="","",IF($C33>=AVERAGE($C$11:$C$46)*1.2,"High",IF($C33>=AVERAGE($C$11:$C$46)*0.7,"Medium","Low"))),"") -> High
B34: =IFERROR(IF($D$4="All India",INDEX({"Andaman and Nicobar Islands";"Andhra Pradesh";"Arunachal Pradesh";"Assam";"Bihar";"Chandigarh";"Chhattisgarh";"Dadra and Nagar Haveli and Daman and Diu";"Delhi";"Goa";"Gujarat";"Haryana";"Himachal Pradesh";"Jammu and Kashmir";"Jharkhand";"Karnataka";"Kerala";"Ladakh";"Lakshadweep";"Madhya Pradesh";"Maharashtra";"Manipur";"Meghalaya";"Mizoram";"Nagaland";"Odisha";"Puducherry";"Punjab";"Rajasthan";"Sikkim";"Tamil Nadu";"Telangana";"Tripura";"Uttar Pradesh";"Uttarakhand";"West Bengal"},24),INDEX('RAW_DISTRICT'!$C$4:$C$745,MATCH(24,'RAW_DISTRICT'!$V$4:$V$745,0))),"") -> Mizoram | C34: =IFERROR(IF($B34="","",SUMIF(IF($D$4="All India",'RAW_DISTRICT'!$B$4:$B$745,'RAW_DISTRICT'!$C$4:$C$745),$B34,'RAW_DISTRICT'!$F$4:$F$745)),"") -> 0 | D34: =IFERROR(IF($B34="","",SUMIF(IF($D$4="All India",'RAW_DISTRICT'!$B$4:$B$745,'RAW_DISTRICT'!$C$4:$C$745),$B34,'RAW_DISTRICT'!$I$4:$I$745)/SUMIF(IF($D$4="All India",'RAW_DISTRICT'!$B$4:$B$745,'RAW_DISTRICT'!$C$4:$C$745),$B34,'RAW_DISTRICT'!$H$4:$H$745)),"") | E34: =IFERROR(IF($B34="","",SUMIF(IF($D$4="All India",'RAW_DISTRICT'!$B$4:$B$745,'RAW_DISTRICT'!$C$4:$C$745),$B34,'RAW_DISTRICT'!$K$4:$K$745)/SUMIF(IF($D$4="All India",'RAW_DISTRICT'!$B$4:$B$745,'RAW_DISTRICT'!$C$4:$C$745),$B34,'RAW_DISTRICT'!$J$4:$J$745)),"") | F34: =IFERROR(IF($C34="","",IF($C34>=AVERAGE($C$11:$C$46)*1.2,"High",IF($C34>=AVERAGE($C$11:$C$46)*0.7,"Medium","Low"))),"") -> High
B35: =IFERROR(IF($D$4="All India",INDEX({"Andaman and Nicobar Islands";"Andhra Pradesh";"Arunachal Pradesh";"Assam";"Bihar";"Chandigarh";"Chhattisgarh";"Dadra and Nagar Haveli and Daman and Diu";"Delhi";"Goa";"Gujarat";"Haryana";"Himachal Pradesh";"Jammu and Kashmir";"Jharkhand";"Karnataka";"Kerala";"Ladakh";"Lakshadweep";"Madhya Pradesh";"Maharashtra";"Manipur";"Meghalaya";"Mizoram";"Nagaland";"Odisha";"Puducherry";"Punjab";"Rajasthan";"Sikkim";"Tamil Nadu";"Telangana";"Tripura";"Uttar Pradesh";"Uttarakhand";"West Bengal"},25),INDEX('RAW_DISTRICT'!$C$4:$C$745,MATCH(25,'RAW_DISTRICT'!$V$4:$V$745,0))),"") -> Nagaland | C35: =IFERROR(IF($B35="","",SUMIF(IF($D$4="All India",'RAW_DISTRICT'!$B$4:$B$745,'RAW_DISTRICT'!$C$4:$C$745),$B35,'RAW_DISTRICT'!$F$4:$F$745)),"") -> 0 | D35: =IFERROR(IF($B35="","",SUMIF(IF($D$4="All India",'RAW_DISTRICT'!$B$4:$B$745,'RAW_DISTRICT'!$C$4:$C$745),$B35,'RAW_DISTRICT'!$I$4:$I$745)/SUMIF(IF($D$4="All India",'RAW_DISTRICT'!$B$4:$B$745,'RAW_DISTRICT'!$C$4:$C$745),$B35,'RAW_DISTRICT'!$H$4:$H$745)),"") | E35: =IFERROR(IF($B35="","",SUMIF(IF($D$4="All India",'RAW_DISTRICT'!$B$4:$B$745,'RAW_DISTRICT'!$C$4:$C$745),$B35,'RAW_DISTRICT'!$K$4:$K$745)/SUMIF(IF($D$4="All India",'RAW_DISTRICT'!$B$4:$B$745,'RAW_DISTRICT'!$C$4:$C$745),$B35,'RAW_DISTRICT'!$J$4:$J$745)),"") | F35: =IFERROR(IF($C35="","",IF($C35>=AVERAGE($C$11:$C$46)*1.2,"High",IF($C35>=AVERAGE($C$11:$C$46)*0.7,"Medium","Low"))),"") -> High
B36: =IFERROR(IF($D$4="All India",INDEX({"Andaman and Nicobar Islands";"Andhra Pradesh";"Arunachal Pradesh";"Assam";"Bihar";"Chandigarh";"Chhattisgarh";"Dadra and Nagar Haveli and Daman and Diu";"Delhi";"Goa";"Gujarat";"Haryana";"Himachal Pradesh";"Jammu and Kashmir";"Jharkhand";"Karnataka";"Kerala";"Ladakh";"Lakshadweep";"Madhya Pradesh";"Maharashtra";"Manipur";"Meghalaya";"Mizoram";"Nagaland";"Odisha";"Puducherry";"Punjab";"Rajasthan";"Sikkim";"Tamil Nadu";"Telangana";"Tripura";"Uttar Pradesh";"Uttarakhand";"West Bengal"},26),INDEX('RAW_DISTRICT'!$C$4:$C$745,MATCH(26,'RAW_DISTRICT'!$V$4:$V$745,0))),"") -> Odisha | C36: =IFERROR(IF($B36="","",SUMIF(IF($D$4="All India",'RAW_DISTRICT'!$B$4:$B$745,'RAW_DISTRICT'!$C$4:$C$745),$B36,'RAW_DISTRICT'!$F$4:$F$745)),"") -> 0 | D36: =IFERROR(IF($B36="","",SUMIF(IF($D$4="All India",'RAW_DISTRICT'!$B$4:$B$745,'RAW_DISTRICT'!$C$4:$C$745),$B36,'RAW_DISTRICT'!$I$4:$I$745)/SUMIF(IF($D$4="All India",'RAW_DISTRICT'!$B$4:$B$745,'RAW_DISTRICT'!$C$4:$C$745),$B36,'RAW_DISTRICT'!$H$4:$H$745)),"") | E36: =IFERROR(IF($B36="","",SUMIF(IF($D$4="All India",'RAW_DISTRICT'!$B$4:$B$745,'RAW_DISTRICT'!$C$4:$C$745),$B36,'RAW_DISTRICT'!$K$4:$K$745)/SUMIF(IF($D$4="All India",'RAW_DISTRICT'!$B$4:$B$745,'RAW_DISTRICT'!$C$4:$C$745),$B36,'RAW_DISTRICT'!$J$4:$J$745)),"") | F36: =IFERROR(IF($C36="","",IF($C36>=AVERAGE($C$11:$C$46)*1.2,"High",IF($C36>=AVERAGE($C$11:$C$46)*0.7,"Medium","Low"))),"") -> High
B37: =IFERROR(IF($D$4="All India",INDEX({"Andaman and Nicobar Islands";"Andhra Pradesh";"Arunachal Pradesh";"Assam";"Bihar";"Chandigarh";"Chhattisgarh";"Dadra and Nagar Haveli and Daman and Diu";"Delhi";"Goa";"Gujarat";"Haryana";"Himachal Pradesh";"Jammu and Kashmir";"Jharkhand";"Karnataka";"Kerala";"Ladakh";"Lakshadweep";"Madhya Pradesh";"Maharashtra";"Manipur";"Meghalaya";"Mizoram";"Nagaland";"Odisha";"Puducherry";"Punjab";"Rajasthan";"Sikkim";"Tamil Nadu";"Telangana";"Tripura";"Uttar Pradesh";"Uttarakhand";"West Bengal"},27),INDEX('RAW_DISTRICT'!$C$4:$C$745,MATCH(27,'RAW_DISTRICT'!$V$4:$V$745,0))),"") -> Puducherry | C37: =IFERROR(IF($B37="","",SUMIF(IF($D$4="All India",'RAW_DISTRICT'!$B$4:$B$745,'RAW_DISTRICT'!$C$4:$C$745),$B37,'RAW_DISTRICT'!$F$4:$F$745)),"") -> 0 | D37: =IFERROR(IF($B37="","",SUMIF(IF($D$4="All India",'RAW_DISTRICT'!$B$4:$B$745,'RAW_DISTRICT'!$C$4:$C$745),$B37,'RAW_DISTRICT'!$I$4:$I$745)/SUMIF(IF($D$4="All India",'RAW_DISTRICT'!$B$4:$B$745,'RAW_DISTRICT'!$C$4:$C$745),$B37,'RAW_DISTRICT'!$H$4:$H$745)),"") | E37: =IFERROR(IF($B37="","",SUMIF(IF($D$4="All India",'RAW_DISTRICT'!$B$4:$B$745,'RAW_DISTRICT'!$C$4:$C$745),$B37,'RAW_DISTRICT'!$K$4:$K$745)/SUMIF(IF($D$4="All India",'RAW_DISTRICT'!$B$4:$B$745,'RAW_DISTRICT'!$C$4:$C$745),$B37,'RAW_DISTRICT'!$J$4:$J$745)),"") | F37: =IFERROR(IF($C37="","",IF($C37>=AVERAGE($C$11:$C$46)*1.2,"High",IF($C37>=AVERAGE($C$11:$C$46)*0.7,"Medium","Low"))),"") -> High
B38: =IFERROR(IF($D$4="All India",INDEX({"Andaman and Nicobar Islands";"Andhra Pradesh";"Arunachal Pradesh";"Assam";"Bihar";"Chandigarh";"Chhattisgarh";"Dadra and Nagar Haveli and Daman and Diu";"Delhi";"Goa";"Gujarat";"Haryana";"Himachal Pradesh";"Jammu and Kashmir";"Jharkhand";"Karnataka";"Kerala";"Ladakh";"Lakshadweep";"Madhya Pradesh";"Maharashtra";"Manipur";"Meghalaya";"Mizoram";"Nagaland";"Odisha";"Puducherry";"Punjab";"Rajasthan";"Sikkim";"Tamil Nadu";"Telangana";"Tripura";"Uttar Pradesh";"Uttarakhand";"West Bengal"},28),INDEX('RAW_DISTRICT'!$C$4:$C$745,MATCH(28,'RAW_DISTRICT'!$V$4:$V$745,0))),"") -> Punjab | C38: =IFERROR(IF($B38="","",SUMIF(IF($D$4="All India",'RAW_DISTRICT'!$B$4:$B$745,'RAW_DISTRICT'!$C$4:$C$745),$B38,'RAW_DISTRICT'!$F$4:$F$745)),"") -> 0 | D38: =IFERROR(IF($B38="","",SUMIF(IF($D$4="All India",'RAW_DISTRICT'!$B$4:$B$745,'RAW_DISTRICT'!$C$4:$C$745),$B38,'RAW_DISTRICT'!$I$4:$I$745)/SUMIF(IF($D$4="All India",'RAW_DISTRICT'!$B$4:$B$745,'RAW_DISTRICT'!$C$4:$C$745),$B38,'RAW_DISTRICT'!$H$4:$H$745)),"") | E38: =IFERROR(IF($B38="","",SUMIF(IF($D$4="All India",'RAW_DISTRICT'!$B$4:$B$745,'RAW_DISTRICT'!$C$4:$C$745),$B38,'RAW_DISTRICT'!$K$4:$K$745)/SUMIF(IF($D$4="All India",'RAW_DISTRICT'!$B$4:$B$745,'RAW_DISTRICT'!$C$4:$C$745),$B38,'RAW_DISTRICT'!$J$4:$J$745)),"") | F38: =IFERROR(IF($C38="","",IF($C38>=AVERAGE($C$11:$C$46)*1.2,"High",IF($C38>=AVERAGE($C$11:$C$46)*0.7,"Medium","Low"))),"") -> High
B39: =IFERROR(IF($D$4="All India",INDEX({"Andaman and Nicobar Islands";"Andhra Pradesh";"Arunachal Pradesh";"Assam";"Bihar";"Chandigarh";"Chhattisgarh";"Dadra and Nagar Haveli and Daman and Diu";"Delhi";"Goa";"Gujarat";"Haryana";"Himachal Pradesh";"Jammu and Kashmir";"Jharkhand";"Karnataka";"Kerala";"Ladakh";"Lakshadweep";"Madhya Pradesh";"Maharashtra";"Manipur";"Meghalaya";"Mizoram";"Nagaland";"Odisha";"Puducherry";"Punjab";"Rajasthan";"Sikkim";"Tamil Nadu";"Telangana";"Tripura";"Uttar Pradesh";"Uttarakhand";"West Bengal"},29),INDEX('RAW_DISTRICT'!$C$4:$C$745,MATCH(29,'RAW_DISTRICT'!$V$4:$V$745,0))),"") -> Rajasthan | C39: =IFERROR(IF($B39="","",SUMIF(IF($D$4="All India",'RAW_DISTRICT'!$B$4:$B$745,'RAW_DISTRICT'!$C$4:$C$745),$B39,'RAW_DISTRICT'!$F$4:$F$745)),"") -> 0 | D39: =IFERROR(IF($B39="","",SUMIF(IF($D$4="All India",'RAW_DISTRICT'!$B$4:$B$745,'RAW_DISTRICT'!$C$4:$C$745),$B39,'RAW_DISTRICT'!$I$4:$I$745)/SUMIF(IF($D$4="All India",'RAW_DISTRICT'!$B$4:$B$745,'RAW_DISTRICT'!$C$4:$C$745),$B39,'RAW_DISTRICT'!$H$4:$H$745)),"") | E39: =IFERROR(IF($B39="","",SUMIF(IF($D$4="All India",'RAW_DISTRICT'!$B$4:$B$745,'RAW_DISTRICT'!$C$4:$C$745),$B39,'RAW_DISTRICT'!$K$4:$K$745)/SUMIF(IF($D$4="All India",'RAW_DISTRICT'!$B$4:$B$745,'RAW_DISTRICT'!$C$4:$C$745),$B39,'RAW_DISTRICT'!$J$4:$J$745)),"") | F39: =IFERROR(IF($C39="","",IF($C39>=AVERAGE($C$11:$C$46)*1.2,"High",IF($C39>=AVERAGE($C$11:$C$46)*0.7,"Medium","Low"))),"") -> High
B40: =IFERROR(IF($D$4="All India",INDEX({"Andaman and Nicobar Islands";"Andhra Pradesh";"Arunachal Pradesh";"Assam";"Bihar";"Chandigarh";"Chhattisgarh";"Dadra and Nagar Haveli and Daman and Diu";"Delhi";"Goa";"Gujarat";"Haryana";"Himachal Pradesh";"Jammu and Kashmir";"Jharkhand";"Karnataka";"Kerala";"Ladakh";"Lakshadweep";"Madhya Pradesh";"Maharashtra";"Manipur";"Meghalaya";"Mizoram";"Nagaland";"Odisha";"Puducherry";"Punjab";"Rajasthan";"Sikkim";"Tamil Nadu";"Telangana";"Tripura";"Uttar Pradesh";"Uttarakhand";"West Bengal"},30),INDEX('RAW_DISTRICT'!$C$4:$C$745,MATCH(30,'RAW_DISTRICT'!$V$4:$V$745,0))),"") -> Sikkim | C40: =IFERROR(IF($B40="","",SUMIF(IF($D$4="All India",'RAW_DISTRICT'!$B$4:$B$745,'RAW_DISTRICT'!$C$4:$C$745),$B40,'RAW_DISTRICT'!$F$4:$F$745)),"") -> 0 | D40: =IFERROR(IF($B40="","",SUMIF(IF($D$4="All India",'RAW_DISTRICT'!$B$4:$B$745,'RAW_DISTRICT'!$C$4:$C$745),$B40,'RAW_DISTRICT'!$I$4:$I$745)/SUMIF(IF($D$4="All India",'RAW_DISTRICT'!$B$4:$B$745,'RAW_DISTRICT'!$C$4:$C$745),$B40,'RAW_DISTRICT'!$H$4:$H$745)),"") | E40: =IFERROR(IF($B40="","",SUMIF(IF($D$4="All India",'RAW_DISTRICT'!$B$4:$B$745,'RAW_DISTRICT'!$C$4:$C$745),$B40,'RAW_DISTRICT'!$K$4:$K$745)/SUMIF(IF($D$4="All India",'RAW_DISTRICT'!$B$4:$B$745,'RAW_DISTRICT'!$C$4:$C$745),$B40,'RAW_DISTRICT'!$J$4:$J$745)),"") | F40: =IFERROR(IF($C40="","",IF($C40>=AVERAGE($C$11:$C$46)*1.2,"High",IF($C40>=AVERAGE($C$11:$C$46)*0.7,"Medium","Low"))),"") -> High
B41: =IFERROR(IF($D$4="All India",INDEX({"Andaman and Nicobar Islands";"Andhra Pradesh";"Arunachal Pradesh";"Assam";"Bihar";"Chandigarh";"Chhattisgarh";"Dadra and Nagar Haveli and Daman and Diu";"Delhi";"Goa";"Gujarat";"Haryana";"Himachal Pradesh";"Jammu and Kashmir";"Jharkhand";"Karnataka";"Kerala";"Ladakh";"Lakshadweep";"Madhya Pradesh";"Maharashtra";"Manipur";"Meghalaya";"Mizoram";"Nagaland";"Odisha";"Puducherry";"Punjab";"Rajasthan";"Sikkim";"Tamil Nadu";"Telangana";"Tripura";"Uttar Pradesh";"Uttarakhand";"West Bengal"},31),INDEX('RAW_DISTRICT'!$C$4:$C$745,MATCH(31,'RAW_DISTRICT'!$V$4:$V$745,0))),"") -> Tamil Nadu | C41: =IFERROR(IF($B41="","",SUMIF(IF($D$4="All India",'RAW_DISTRICT'!$B$4:$B$745,'RAW_DISTRICT'!$C$4:$C$745),$B41,'RAW_DISTRICT'!$F$4:$F$745)),"") -> 0 | D41: =IFERROR(IF($B41="","",SUMIF(IF($D$4="All India",'RAW_DISTRICT'!$B$4:$B$745,'RAW_DISTRICT'!$C$4:$C$745),$B41,'RAW_DISTRICT'!$I$4:$I$745)/SUMIF(IF($D$4="All India",'RAW_DISTRICT'!$B$4:$B$745,'RAW_DISTRICT'!$C$4:$C$745),$B41,'RAW_DISTRICT'!$H$4:$H$745)),"") | E41: =IFERROR(IF($B41="","",SUMIF(IF($D$4="All India",'RAW_DISTRICT'!$B$4:$B$745,'RAW_DISTRICT'!$C$4:$C$745),$B41,'RAW_DISTRICT'!$K$4:$K$745)/SUMIF(IF($D$4="All India",'RAW_DISTRICT'!$B$4:$B$745,'RAW_DISTRICT'!$C$4:$C$745),$B41,'RAW_DISTRICT'!$J$4:$J$745)),"") | F41: =IFERROR(IF($C41="","",IF($C41>=AVERAGE($C$11:$C$46)*1.2,"High",IF($C41>=AVERAGE($C$11:$C$46)*0.7,"Medium","Low"))),"") -> High
B42: =IFERROR(IF($D$4="All India",INDEX({"Andaman and Nicobar Islands";"Andhra Pradesh";"Arunachal Pradesh";"Assam";"Bihar";"Chandigarh";"Chhattisgarh";"Dadra and Nagar Haveli and Daman and Diu";"Delhi";"Goa";"Gujarat";"Haryana";"Himachal Pradesh";"Jammu and Kashmir";"Jharkhand";"Karnataka";"Kerala";"Ladakh";"Lakshadweep";"Madhya Pradesh";"Maharashtra";"Manipur";"Meghalaya";"Mizoram";"Nagaland";"Odisha";"Puducherry";"Punjab";"Rajasthan";"Sikkim";"Tamil Nadu";"Telangana";"Tripura";"Uttar Pradesh";"Uttarakhand";"West Bengal"},32),INDEX('RAW_DISTRICT'!$C$4:$C$745,MATCH(32,'RAW_DISTRICT'!$V$4:$V$745,0))),"") -> Telangana | C42: =IFERROR(IF($B42="","",SUMIF(IF($D$4="All India",'RAW_DISTRICT'!$B$4:$B$745,'RAW_DISTRICT'!$C$4:$C$745),$B42,'RAW_DISTRICT'!$F$4:$F$745)),"") -> 0 | D42: =IFERROR(IF($B42="","",SUMIF(IF($D$4="All India",'RAW_DISTRICT'!$B$4:$B$745,'RAW_DISTRICT'!$C$4:$C$745),$B42,'RAW_DISTRICT'!$I$4:$I$745)/SUMIF(IF($D$4="All India",'RAW_DISTRICT'!$B$4:$B$745,'RAW_DISTRICT'!$C$4:$C$745),$B42,'RAW_DISTRICT'!$H$4:$H$745)),"") | E42: =IFERROR(IF($B42="","",SUMIF(IF($D$4="All India",'RAW_DISTRICT'!$B$4:$B$745,'RAW_DISTRICT'!$C$4:$C$745),$B42,'RAW_DISTRICT'!$K$4:$K$745)/SUMIF(IF($D$4="All India",'RAW_DISTRICT'!$B$4:$B$745,'RAW_DISTRICT'!$C$4:$C$745),$B42,'RAW_DISTRICT'!$J$4:$J$745)),"") | F42: =IFERROR(IF($C42="","",IF($C42>=AVERAGE($C$11:$C$46)*1.2,"High",IF($C42>=AVERAGE($C$11:$C$46)*0.7,"Medium","Low"))),"") -> High
B43: =IFERROR(IF($D$4="All India",INDEX({"Andaman and Nicobar Islands";"Andhra Pradesh";"Arunachal Pradesh";"Assam";"Bihar";"Chandigarh";"Chhattisgarh";"Dadra and Nagar Haveli and Daman and Diu";"Delhi";"Goa";"Gujarat";"Haryana";"Himachal Pradesh";"Jammu and Kashmir";"Jharkhand";"Karnataka";"Kerala";"Ladakh";"Lakshadweep";"Madhya Pradesh";"Maharashtra";"Manipur";"Meghalaya";"Mizoram";"Nagaland";"Odisha";"Puducherry";"Punjab";"Rajasthan";"Sikkim";"Tamil Nadu";"Telangana";"Tripura";"Uttar Pradesh";"Uttarakhand";"West Bengal"},33),INDEX('RAW_DISTRICT'!$C$4:$C$745,MATCH(33,'RAW_DISTRICT'!$V$4:$V$745,0))),"") -> Tripura | C43: =IFERROR(IF($B43="","",SUMIF(IF($D$4="All India",'RAW_DISTRICT'!$B$4:$B$745,'RAW_DISTRICT'!$C$4:$C$745),$B43,'RAW_DISTRICT'!$F$4:$F$745)),"") -> 0 | D43: =IFERROR(IF($B43="","",SUMIF(IF($D$4="All India",'RAW_DISTRICT'!$B$4:$B$745,'RAW_DISTRICT'!$C$4:$C$745),$B43,'RAW_DISTRICT'!$I$4:$I$745)/SUMIF(IF($D$4="All India",'RAW_DISTRICT'!$B$4:$B$745,'RAW_DISTRICT'!$C$4:$C$745),$B43,'RAW_DISTRICT'!$H$4:$H$745)),"") | E43: =IFERROR(IF($B43="","",SUMIF(IF($D$4="All India",'RAW_DISTRICT'!$B$4:$B$745,'RAW_DISTRICT'!$C$4:$C$745),$B43,'RAW_DISTRICT'!$K$4:$K$745)/SUMIF(IF($D$4="All India",'RAW_DISTRICT'!$B$4:$B$745,'RAW_DISTRICT'!$C$4:$C$745),$B43,'RAW_DISTRICT'!$J$4:$J$745)),"") | F43: =IFERROR(IF($C43="","",IF($C43>=AVERAGE($C$11:$C$46)*1.2,"High",IF($C43>=AVERAGE($C$11:$C$46)*0.7,"Medium","Low"))),"") -> High
...

Sheet 03. Reach & Engagement
A1: REACH & ENGAGEMENT ANALYTICS
A2: =IF(SelectedScope="All India","NATIONAL VIEW — ALL INDIA","STATE VIEW — "&SelectedScope) -> NATIONAL VIEW — ALL INDIA
A3: All figures are LIVE FORMULAS reading from RAW_DISTRICT. Change the scope in Sheet 02 to recalculate this entire sheet.
A4: REACH KPIs
A5: # | B5: Metric | C5: Value | D5: Benchmark | E5: Meets Benchmark? | F5: Districts Reporting | G5: Schools Active | H5: Connectivity Mode (Most Common) | I5: Notes
A6: 1 | B6: Total Active Users | C6: =SUMPRODUCT((IF(SelectedScope="All India",1,'RAW_DISTRICT'!$B$4:$B$745=SelectedScope))*'RAW_DISTRICT'!$F$4:$F$745) -> 0 | D6: — | F6: =IF(SelectedScope="All India",COUNTA('RAW_DISTRICT'!$C$4:$C$745),COUNTIFS('RAW_DISTRICT'!$B$4:$B$745,SelectedScope)) -> 742
A7: 2 | B7: Avg Daily Active Users (DAU) | C7: =IFERROR((SUMPRODUCT((IF(SelectedScope="All India",1,'RAW_DISTRICT'!$B$4:$B$745=SelectedScope))*'RAW_DISTRICT'!$G$4:$G$745))/(IF(SelectedScope="All India",COUNTA('RAW_DISTRICT'!$C$4:$C$745),COUNTIFS('RAW_DISTRICT'!$B$4:$B$745,SelectedScope))),"") -> 0 | D7: —
A8: 3 | B8: Total Sessions | C8: =SUMPRODUCT((IF(SelectedScope="All India",1,'RAW_DISTRICT'!$B$4:$B$745=SelectedScope))*'RAW_DISTRICT'!$L$4:$L$745) -> 0 | D8: —
A9: 4 | B9: Offline Sessions | C9: =SUMPRODUCT((IF(SelectedScope="All India",1,'RAW_DISTRICT'!$B$4:$B$745=SelectedScope))*'RAW_DISTRICT'!$M$4:$M$745) -> 0 | D9: —
A10: 5 | B10: Offline Usage % | C10: =IFERROR((SUMPRODUCT((IF(SelectedScope="All India",1,'RAW_DISTRICT'!$B$4:$B$745=SelectedScope))*'RAW_DISTRICT'!$M$4:$M$745))/(SUMPRODUCT((IF(SelectedScope="All India",1,'RAW_DISTRICT'!$B$4:$B$745=SelectedScope))*'RAW_DISTRICT'!$L$4:$L$745)),"") | D10: < 20% | E10: =IFERROR(IF(C10="","",IF(LEFT(D10,1)="≥",C10>=VALUE(SUBSTITUTE(SUBSTITUTE(D10,"≥ ",""),"%",""))/100,IF(LEFT(D10,1)="<",C10<VALUE(SUBSTITUTE(SUBSTITUTE(D10,"< ",""),"%",""))/100,""))),"")
A11: 6 | B11: AR Sessions | C11: =SUMPRODUCT((IF(SelectedScope="All India",1,'RAW_DISTRICT'!$B$4:$B$745=SelectedScope))*'RAW_DISTRICT'!$J$4:$J$745) -> 0 | D11: —
A12: 7 | B12: AR Module Completion % | C12: =IFERROR((SUMPRODUCT((IF(SelectedScope="All India",1,'RAW_DISTRICT'!$B$4:$B$745=SelectedScope))*'RAW_DISTRICT'!$K$4:$K$745))/(SUMPRODUCT((IF(SelectedScope="All India",1,'RAW_DISTRICT'!$B$4:$B$745=SelectedScope))*'RAW_DISTRICT'!$J$4:$J$745)),"") | D12: ≥ 65% | E12: =IFERROR(IF(C12="","",IF(LEFT(D12,1)="≥",C12>=VALUE(SUBSTITUTE(SUBSTITUTE(D12,"≥ ",""),"%",""))/100,IF(LEFT(D12,1)="<",C12<VALUE(SUBSTITUTE(SUBSTITUTE(D12,"< ",""),"%",""))/100,""))),"")
A13: 8 | B13: Quiz Attempts | C13: =SUMPRODUCT((IF(SelectedScope="All India",1,'RAW_DISTRICT'!$B$4:$B$745=SelectedScope))*'RAW_DISTRICT'!$H$4:$H$745) -> 0 | D13: —
A14: 9 | B14: Avg Quiz Score % | C14: =IFERROR((SUMPRODUCT((IF(SelectedScope="All India",1,'RAW_DISTRICT'!$B$4:$B$745=SelectedScope))*'RAW_DISTRICT'!$I$4:$I$745))/(SUMPRODUCT((IF(SelectedScope="All India",1,'RAW_DISTRICT'!$B$4:$B$745=SelectedScope))*'RAW_DISTRICT'!$H$4:$H$745)),"") | D14: ≥ 60% | E14: =IFERROR(IF(C14="","",IF(LEFT(D14,1)="≥",C14>=VALUE(SUBSTITUTE(SUBSTITUTE(D14,"≥ ",""),"%",""))/100,IF(LEFT(D14,1)="<",C14<VALUE(SUBSTITUTE(SUBSTITUTE(D14,"< ",""),"%",""))/100,""))),"")
A15: 10 | B15: AR-Capable Device % | C15: =IFERROR((SUMPRODUCT((IF(SelectedScope="All India",1,'RAW_DISTRICT'!$B$4:$B$745=SelectedScope))*'RAW_DISTRICT'!$N$4:$N$745))/(SUMPRODUCT((IF(SelectedScope="All India",1,'RAW_DISTRICT'!$B$4:$B$745=SelectedScope))*'RAW_DISTRICT'!$O$4:$O$745)),"") | D15: ≥ 70% | E15: =IFERROR(IF(C15="","",IF(LEFT(D15,1)="≥",C15>=VALUE(SUBSTITUTE(SUBSTITUTE(D15,"≥ ",""),"%",""))/100,IF(LEFT(D15,1)="<",C15<VALUE(SUBSTITUTE(SUBSTITUTE(D15,"< ",""),"%",""))/100,""))),"")
A16: 11 | B16: Schools Active | C16: =SUMPRODUCT((IF(SelectedScope="All India",1,'RAW_DISTRICT'!$B$4:$B$745=SelectedScope))*'RAW_DISTRICT'!$P$4:$P$745) -> 0 | D16: —
A17: 12 | B17: Teacher Logins (Total) | C17: =SUMPRODUCT((IF(SelectedScope="All India",1,'RAW_DISTRICT'!$B$4:$B$745=SelectedScope))*'RAW_DISTRICT'!$Q$4:$Q$745) -> 0 | D17: —
A19: ENGAGEMENT TIER BREAKDOWN
A20: # | B20: Tier (by Active Users per District) | C20: Definition | D20: District Count | E20: % of Districts | F20: Avg Quiz Score in Tier | G20: Avg AR Completion in Tier | H20: Top District in Tier | I20: Notes
A21: 1 | B21: High Engagement Districts | C21: Active users ≥ 80th percentile | D21: =SUMPRODUCT((IF(SelectedScope="All India",1,'RAW_DISTRICT'!$B$4:$B$745=SelectedScope))*('RAW_DISTRICT'!$F$4:$F$745>=$I$61)) -> 742 | E21: =IFERROR(D21/IF(SelectedScope="All India",COUNTA('RAW_DISTRICT'!$C$4:$C$745),COUNTIFS('RAW_DISTRICT'!$B$4:$B$745,SelectedScope)),"") -> 1
A22: 2 | B22: Medium Engagement Districts | C22: Active users 40th–80th percentile | D22: =SUMPRODUCT((IF(SelectedScope="All India",1,'RAW_DISTRICT'!$B$4:$B$745=SelectedScope))*('RAW_DISTRICT'!$F$4:$F$745>=$I$60)*('RAW_DISTRICT'!$F$4:$F$745<$I$61)) -> 0 | E22: =IFERROR(D22/IF(SelectedScope="All India",COUNTA('RAW_DISTRICT'!$C$4:$C$745),COUNTIFS('RAW_DISTRICT'!$B$4:$B$745,SelectedScope)),"") -> 0
A23: 3 | B23: Low Engagement Districts | C23: Active users > 0, < 40th percentile | D23: =SUMPRODUCT((IF(SelectedScope="All India",1,'RAW_DISTRICT'!$B$4:$B$745=SelectedScope))*('RAW_DISTRICT'!$F$4:$F$745>0)*('RAW_DISTRICT'!$F$4:$F$745<$I$60)) -> 0 | E23: =IFERROR(D23/IF(SelectedScope="All India",COUNTA('RAW_DISTRICT'!$C$4:$C$745),COUNTIFS('RAW_DISTRICT'!$B$4:$B$745,SelectedScope)),"") -> 0
A24: 4 | B24: Zero-Activity Districts | C24: No recorded active users this month | D24: =SUMPRODUCT((IF(SelectedScope="All India",1,'RAW_DISTRICT'!$B$4:$B$745=SelectedScope))*('RAW_DISTRICT'!$F$4:$F$745=0)) -> 742 | E24: =IFERROR(D24/IF(SelectedScope="All India",COUNTA('RAW_DISTRICT'!$C$4:$C$745),COUNTIFS('RAW_DISTRICT'!$B$4:$B$745,SelectedScope)),"") -> 1
H60: P40_THRESHOLD (helper - do not edit) | I60: {=PERCENTILE(IF(SelectedScope="All India",N('RAW_DISTRICT'!$F$4:$F$745),IF('RAW_DISTRICT'!$B$4:$B$745=SelectedScope,N('RAW_DISTRICT'!$F$4:$F$745),0)),0.4)} -> 0
H61: P80_THRESHOLD (helper - do not edit) | I61: {=PERCENTILE(IF(SelectedScope="All India",N('RAW_DISTRICT'!$F$4:$F$745),IF('RAW_DISTRICT'!$B$4:$B$745=SelectedScope,N('RAW_DISTRICT'!$F$4:$F$745),0)),0.8)} -> 0

Sheet 04. Learning Outcomes
A1: LEARNING OUTCOMES ANALYTICS
A2: =IF(SelectedScope="All India","NATIONAL VIEW — ALL INDIA","STATE VIEW — "&SelectedScope) -> NATIONAL VIEW — ALL INDIA
A3: SOURCE: RAW_AR_CONTENT (Dashboard Curriculum Map) + RAW_QUIZ (Dashboard Quiz Management). Every row below is a LIVE FORMULA — no manual entry.
A4: A. PRE vs POST AR MODULE SCORE — BY SUBJECT (from Published AR Content)
A5: # | B5: Subject | C5: Modules Published | D5: Avg Pre-Module Score % | E5: Avg Post-Module Score % | F5: Score Uplift (pp) | G5: AR Completion % | H5: Quizzes Published | I5: Avg Quiz Score % | J5: Notes
